[2021-04-05 17:19:18,050] DEBUG in root: Upstream URL: http://localhost:5200/
[2021-04-05 17:19:22,872] DEBUG in root: Upstream URL: http://localhost:5200/users
[2021-04-05 17:19:28,458] DEBUG in root: Upstream URL: http://localhost:5200/users
[2021-04-05 17:20:54,852] DEBUG in root: Upstream URL: http://localhost:5200/users
[2021-04-05 17:24:16,737] DEBUG in root: Upstream URL: http://localhost:5200/users
[2021-04-05 17:25:14,298] DEBUG in root: Upstream URL: http://localhost:5200/users
[2021-04-05 17:29:48,517] DEBUG in root: Upstream URL: http://localhost:5200/users
[2021-04-05 17:29:48,519] ERROR in root: HTTPConnectionPool(host='localhost', port=5200): Max retries exceeded with url: /users (Caused by NewConnectionError('<urllib3.connection.HTTPConnection object at 0x7fc5b76734f0>: Failed to establish a new connection: [Errno 111] Connection refused'))
Traceback (most recent call last):
  File "/usr/lib/python3/dist-packages/urllib3/connection.py", line 159, in _new_conn
    conn = connection.create_connection(
  File "/usr/lib/python3/dist-packages/urllib3/util/connection.py", line 84, in create_connection
    raise err
  File "/usr/lib/python3/dist-packages/urllib3/util/connection.py", line 74, in create_connection
    sock.connect(sa)
ConnectionRefusedError: [Errno 111] Connection refused

During handling of the above exception, another exception occurred:

Traceback (most recent call last):
  File "/usr/lib/python3/dist-packages/urllib3/connectionpool.py", line 665, in urlopen
    httplib_response = self._make_request(
  File "/usr/lib/python3/dist-packages/urllib3/connectionpool.py", line 387, in _make_request
    conn.request(method, url, **httplib_request_kw)
  File "/usr/lib/python3.8/http/client.py", line 1255, in request
    self._send_request(method, url, body, headers, encode_chunked)
  File "/usr/lib/python3.8/http/client.py", line 1301, in _send_request
    self.endheaders(body, encode_chunked=encode_chunked)
  File "/usr/lib/python3.8/http/client.py", line 1250, in endheaders
    self._send_output(message_body, encode_chunked=encode_chunked)
  File "/usr/lib/python3.8/http/client.py", line 1010, in _send_output
    self.send(msg)
  File "/usr/lib/python3.8/http/client.py", line 950, in send
    self.connect()
  File "/usr/lib/python3/dist-packages/urllib3/connection.py", line 187, in connect
    conn = self._new_conn()
  File "/usr/lib/python3/dist-packages/urllib3/connection.py", line 171, in _new_conn
    raise NewConnectionError(
urllib3.exceptions.NewConnectionError: <urllib3.connection.HTTPConnection object at 0x7fc5b76734f0>: Failed to establish a new connection: [Errno 111] Connection refused

During handling of the above exception, another exception occurred:

Traceback (most recent call last):
  File "/usr/lib/python3/dist-packages/requests/adapters.py", line 439, in send
    resp = conn.urlopen(
  File "/usr/lib/python3/dist-packages/urllib3/connectionpool.py", line 719, in urlopen
    retries = retries.increment(
  File "/usr/lib/python3/dist-packages/urllib3/util/retry.py", line 436, in increment
    raise MaxRetryError(_pool, url, error or ResponseError(cause))
urllib3.exceptions.MaxRetryError: HTTPConnectionPool(host='localhost', port=5200): Max retries exceeded with url: /users (Caused by NewConnectionError('<urllib3.connection.HTTPConnection object at 0x7fc5b76734f0>: Failed to establish a new connection: [Errno 111] Connection refused'))

During handling of the above exception, another exception occurred:

Traceback (most recent call last):
  File "./gateway.py", line 96, in gateway
    upstream_response = requests.request(
  File "/usr/lib/python3/dist-packages/requests/api.py", line 60, in request
    return session.request(method=method, url=url, **kwargs)
  File "/usr/lib/python3/dist-packages/requests/sessions.py", line 533, in request
    resp = self.send(prep, **send_kwargs)
  File "/usr/lib/python3/dist-packages/requests/sessions.py", line 646, in send
    r = adapter.send(request, **kwargs)
  File "/usr/lib/python3/dist-packages/requests/adapters.py", line 516, in send
    raise ConnectionError(e, request=request)
requests.exceptions.ConnectionError: HTTPConnectionPool(host='localhost', port=5200): Max retries exceeded with url: /users (Caused by NewConnectionError('<urllib3.connection.HTTPConnection object at 0x7fc5b76734f0>: Failed to establish a new connection: [Errno 111] Connection refused'))
[2021-04-05 17:30:14,364] DEBUG in root: Upstream URL: http://localhost:5100/users
[2021-04-07 19:56:21,625] DEBUG in root: Upstream URL: http://localhost:5100/users
[2021-04-07 19:57:37,655] DEBUG in root: Upstream URL: http://localhost:5100/users
[2021-04-07 20:00:28,545] DEBUG in root: Upstream URL: http://localhost:5100/users
[2021-04-07 20:02:46,618] DEBUG in root: Upstream URL: http://localhost:5100/users
[2021-04-07 20:04:25,879] DEBUG in root: Upstream URL: http://localhost:5100/users
[2021-04-07 20:05:30,209] DEBUG in root: Upstream URL: http://localhost:5100/users
[2021-04-07 20:12:17,808] DEBUG in root: Upstream URL: http://localhost:5200/timeline
[2021-04-07 20:31:24,955] DEBUG in root: Upstream URL: http://localhost:5200/cfreen0
[2021-04-07 20:35:31,765] DEBUG in root: Upstream URL: http://localhost:5100/
[2021-04-07 20:35:34,966] DEBUG in root: Upstream URL: http://localhost:5200/['cfreen0']
[2021-04-07 20:36:19,109] DEBUG in root: Upstream URL: http://localhost:5200/cfreen0
[2021-04-07 20:37:14,405] DEBUG in root: Upstream URL: http://localhost:5100/
[2021-04-07 20:37:16,149] DEBUG in root: Upstream URL: http://localhost:5200/cfreen0
[2021-04-07 20:37:18,111] DEBUG in root: Upstream URL: http://localhost:5100/
